[2024-10-08 15:10:07] [INFO    ] discord.client: logging in using static token
[2024-10-08 15:10:09] [INFO    ] discord.gateway: Shard ID None has connected to Gateway (Session ID: 57681545736a32f4b9e1deb0e31656de).
[2024-10-08 15:35:48] [INFO    ] discord.gateway: Shard ID None session has been invalidated.
[2024-10-08 15:35:54] [INFO    ] discord.gateway: Shard ID None has connected to Gateway (Session ID: be4799dc49b7d4d77e75ae2f15a53dff).
[2024-10-08 15:51:26] [INFO    ] discord.gateway: Shard ID None session has been invalidated.
[2024-10-08 15:51:32] [INFO    ] discord.gateway: Shard ID None has connected to Gateway (Session ID: 10325676861ba1667cd1c825824bf014).
[2024-10-08 16:15:27] [INFO    ] discord.gateway: Shard ID None session has been invalidated.
[2024-10-08 16:15:33] [INFO    ] discord.gateway: Shard ID None has connected to Gateway (Session ID: 3c12bd4c63ac95fd1bf181ffd60a6f5f).
[2024-10-08 16:34:22] [INFO    ] discord.gateway: Shard ID None session has been invalidated.
[2024-10-08 16:34:27] [INFO    ] discord.gateway: Shard ID None has connected to Gateway (Session ID: 41975a361298fba83f1485dce7262d10).
[2024-10-08 16:55:52] [WARNING ] discord.gateway: Can't keep up, shard ID None websocket is 29.1s behind.
[2024-10-08 16:56:54] [WARNING ] discord.gateway: Can't keep up, shard ID None websocket is 38.0s behind.
[2024-10-08 17:08:26] [ERROR   ] discord.ext.commands.bot: Ignoring exception in command None
discord.ext.commands.errors.CommandNotFound: Command "pring" is not found
[2024-10-08 18:35:32] [ERROR   ] discord.client: Attempting a reconnect in 0.87s
Traceback (most recent call last):
  File "/Users/tyson/my-discord-bot/venv/lib/python3.12/site-packages/discord/client.py", line 667, in connect
    await self.ws.poll_event()
  File "/Users/tyson/my-discord-bot/venv/lib/python3.12/site-packages/discord/gateway.py", line 625, in poll_event
    await self.received_message(msg.data)
  File "/Users/tyson/my-discord-bot/venv/lib/python3.12/site-packages/discord/gateway.py", line 533, in received_message
    await self.send_as_json(beat)
  File "/Users/tyson/my-discord-bot/venv/lib/python3.12/site-packages/discord/gateway.py", line 661, in send_as_json
    await self.send(utils._to_json(data))
  File "/Users/tyson/my-discord-bot/venv/lib/python3.12/site-packages/discord/gateway.py", line 657, in send
    await self.socket.send_str(data)
  File "/Users/tyson/my-discord-bot/venv/lib/python3.12/site-packages/aiohttp/client_ws.py", line 226, in send_str
    await self._writer.send(data, binary=False, compress=compress)
  File "/Users/tyson/my-discord-bot/venv/lib/python3.12/site-packages/aiohttp/http_websocket.py", line 750, in send
    await self._send_frame(message, WSMsgType.TEXT, compress)
  File "/Users/tyson/my-discord-bot/venv/lib/python3.12/site-packages/aiohttp/http_websocket.py", line 690, in _send_frame
    self._write(header + mask + message)
  File "/Users/tyson/my-discord-bot/venv/lib/python3.12/site-packages/aiohttp/http_websocket.py", line 723, in _write
    raise ClientConnectionResetError("Cannot write to closing transport")
aiohttp.client_exceptions.ClientConnectionResetError: Cannot write to closing transport
[2024-10-08 18:35:34] [INFO    ] discord.gateway: Shard ID None has successfully RESUMED session 41975a361298fba83f1485dce7262d10.
[2024-10-08 18:53:36] [INFO    ] discord.gateway: Shard ID None session has been invalidated.
[2024-10-08 18:53:42] [INFO    ] discord.gateway: Shard ID None has connected to Gateway (Session ID: 5a8c2244c49f7444df7d4c3585417bfb).
[2024-10-08 18:55:41] [INFO    ] discord.gateway: Shard ID None has successfully RESUMED session 5a8c2244c49f7444df7d4c3585417bfb.
[2024-10-08 19:12:32] [INFO    ] discord.gateway: Shard ID None session has been invalidated.
[2024-10-08 19:12:38] [INFO    ] discord.gateway: Shard ID None has connected to Gateway (Session ID: 0ae1ddbdd35294cf7739901c2716cc46).
[2024-10-08 20:27:06] [INFO    ] discord.gateway: Shard ID None has successfully RESUMED session 0ae1ddbdd35294cf7739901c2716cc46.
[2024-10-08 20:36:52] [WARNING ] discord.gateway: Can't keep up, shard ID None websocket is 22.4s behind.
[2024-10-08 21:34:05] [ERROR   ] discord.client: Attempting a reconnect in 0.11s
Traceback (most recent call last):
  File "/Users/tyson/my-discord-bot/venv/lib/python3.12/site-packages/aiohttp/connector.py", line 1294, in _create_direct_connection
    hosts = await self._resolve_host(host, port, traces=traces)
            ^^^^^^^^^^^^^^^^^^^^^^^^^^^^^^^^^^^^^^^^^^^^^^^^^^^
  File "/Users/tyson/my-discord-bot/venv/lib/python3.12/site-packages/aiohttp/connector.py", line 945, in _resolve_host
    return await asyncio.shield(resolved_host_task)
           ^^^^^^^^^^^^^^^^^^^^^^^^^^^^^^^^^^^^^^^^
  File "/Users/tyson/my-discord-bot/venv/lib/python3.12/site-packages/aiohttp/connector.py", line 982, in _resolve_host_with_throttle
    addrs = await self._resolver.resolve(host, port, family=self._family)
            ^^^^^^^^^^^^^^^^^^^^^^^^^^^^^^^^^^^^^^^^^^^^^^^^^^^^^^^^^^^^^
  File "/Users/tyson/my-discord-bot/venv/lib/python3.12/site-packages/aiohttp/resolver.py", line 38, in resolve
    infos = await self._loop.getaddrinfo(
            ^^^^^^^^^^^^^^^^^^^^^^^^^^^^^
  File "/Library/Frameworks/Python.framework/Versions/3.12/lib/python3.12/asyncio/base_events.py", line 878, in getaddrinfo
    return await self.run_in_executor(
           ^^^^^^^^^^^^^^^^^^^^^^^^^^^
  File "/Library/Frameworks/Python.framework/Versions/3.12/lib/python3.12/concurrent/futures/thread.py", line 58, in run
    result = self.fn(*self.args, **self.kwargs)
             ^^^^^^^^^^^^^^^^^^^^^^^^^^^^^^^^^^
  File "/Library/Frameworks/Python.framework/Versions/3.12/lib/python3.12/socket.py", line 963, in getaddrinfo
    for res in _socket.getaddrinfo(host, port, family, type, proto, flags):
               ^^^^^^^^^^^^^^^^^^^^^^^^^^^^^^^^^^^^^^^^^^^^^^^^^^^^^^^^^^^
socket.gaierror: [Errno 8] nodename nor servname provided, or not known

The above exception was the direct cause of the following exception:

Traceback (most recent call last):
  File "/Users/tyson/my-discord-bot/venv/lib/python3.12/site-packages/discord/client.py", line 664, in connect
    self.ws = await asyncio.wait_for(coro, timeout=60.0)
              ^^^^^^^^^^^^^^^^^^^^^^^^^^^^^^^^^^^^^^^^^^
  File "/Library/Frameworks/Python.framework/Versions/3.12/lib/python3.12/asyncio/tasks.py", line 510, in wait_for
    return await fut
           ^^^^^^^^^
  File "/Users/tyson/my-discord-bot/venv/lib/python3.12/site-packages/discord/gateway.py", line 374, in from_client
    socket = await client.http.ws_connect(str(url))
             ^^^^^^^^^^^^^^^^^^^^^^^^^^^^^^^^^^^^^^
  File "/Users/tyson/my-discord-bot/venv/lib/python3.12/site-packages/discord/http.py", line 550, in ws_connect
    return await self.__session.ws_connect(url, **kwargs)
           ^^^^^^^^^^^^^^^^^^^^^^^^^^^^^^^^^^^^^^^^^^^^^^
  File "/Users/tyson/my-discord-bot/venv/lib/python3.12/site-packages/aiohttp/client.py", line 935, in _ws_connect
    resp = await self.request(
           ^^^^^^^^^^^^^^^^^^^
  File "/Users/tyson/my-discord-bot/venv/lib/python3.12/site-packages/aiohttp/client.py", line 661, in _request
    conn = await self._connector.connect(
           ^^^^^^^^^^^^^^^^^^^^^^^^^^^^^^
  File "/Users/tyson/my-discord-bot/venv/lib/python3.12/site-packages/aiohttp/connector.py", line 556, in connect
    proto = await self._create_connection(req, traces, timeout)
            ^^^^^^^^^^^^^^^^^^^^^^^^^^^^^^^^^^^^^^^^^^^^^^^^^^^
  File "/Users/tyson/my-discord-bot/venv/lib/python3.12/site-packages/aiohttp/connector.py", line 1009, in _create_connection
    _, proto = await self._create_direct_connection(req, traces, timeout)
               ^^^^^^^^^^^^^^^^^^^^^^^^^^^^^^^^^^^^^^^^^^^^^^^^^^^^^^^^^^
  File "/Users/tyson/my-discord-bot/venv/lib/python3.12/site-packages/aiohttp/connector.py", line 1300, in _create_direct_connection
    raise ClientConnectorError(req.connection_key, exc) from exc
aiohttp.client_exceptions.ClientConnectorError: Cannot connect to host gateway-us-east1-d.discord.gg:443 ssl:default [nodename nor servname provided, or not known]
[2024-10-08 21:34:06] [ERROR   ] discord.client: Attempting a reconnect in 3.80s
Traceback (most recent call last):
  File "/Users/tyson/my-discord-bot/venv/lib/python3.12/site-packages/aiohttp/connector.py", line 1294, in _create_direct_connection
    hosts = await self._resolve_host(host, port, traces=traces)
            ^^^^^^^^^^^^^^^^^^^^^^^^^^^^^^^^^^^^^^^^^^^^^^^^^^^
  File "/Users/tyson/my-discord-bot/venv/lib/python3.12/site-packages/aiohttp/connector.py", line 945, in _resolve_host
    return await asyncio.shield(resolved_host_task)
           ^^^^^^^^^^^^^^^^^^^^^^^^^^^^^^^^^^^^^^^^
  File "/Users/tyson/my-discord-bot/venv/lib/python3.12/site-packages/aiohttp/connector.py", line 982, in _resolve_host_with_throttle
    addrs = await self._resolver.resolve(host, port, family=self._family)
            ^^^^^^^^^^^^^^^^^^^^^^^^^^^^^^^^^^^^^^^^^^^^^^^^^^^^^^^^^^^^^
  File "/Users/tyson/my-discord-bot/venv/lib/python3.12/site-packages/aiohttp/resolver.py", line 38, in resolve
    infos = await self._loop.getaddrinfo(
            ^^^^^^^^^^^^^^^^^^^^^^^^^^^^^
  File "/Library/Frameworks/Python.framework/Versions/3.12/lib/python3.12/asyncio/base_events.py", line 878, in getaddrinfo
    return await self.run_in_executor(
           ^^^^^^^^^^^^^^^^^^^^^^^^^^^
  File "/Library/Frameworks/Python.framework/Versions/3.12/lib/python3.12/concurrent/futures/thread.py", line 58, in run
    result = self.fn(*self.args, **self.kwargs)
             ^^^^^^^^^^^^^^^^^^^^^^^^^^^^^^^^^^
  File "/Library/Frameworks/Python.framework/Versions/3.12/lib/python3.12/socket.py", line 963, in getaddrinfo
    for res in _socket.getaddrinfo(host, port, family, type, proto, flags):
               ^^^^^^^^^^^^^^^^^^^^^^^^^^^^^^^^^^^^^^^^^^^^^^^^^^^^^^^^^^^
socket.gaierror: [Errno 8] nodename nor servname provided, or not known

The above exception was the direct cause of the following exception:

Traceback (most recent call last):
  File "/Users/tyson/my-discord-bot/venv/lib/python3.12/site-packages/discord/client.py", line 664, in connect
    self.ws = await asyncio.wait_for(coro, timeout=60.0)
              ^^^^^^^^^^^^^^^^^^^^^^^^^^^^^^^^^^^^^^^^^^
  File "/Library/Frameworks/Python.framework/Versions/3.12/lib/python3.12/asyncio/tasks.py", line 510, in wait_for
    return await fut
           ^^^^^^^^^
  File "/Users/tyson/my-discord-bot/venv/lib/python3.12/site-packages/discord/gateway.py", line 374, in from_client
    socket = await client.http.ws_connect(str(url))
             ^^^^^^^^^^^^^^^^^^^^^^^^^^^^^^^^^^^^^^
  File "/Users/tyson/my-discord-bot/venv/lib/python3.12/site-packages/discord/http.py", line 550, in ws_connect
    return await self.__session.ws_connect(url, **kwargs)
           ^^^^^^^^^^^^^^^^^^^^^^^^^^^^^^^^^^^^^^^^^^^^^^
  File "/Users/tyson/my-discord-bot/venv/lib/python3.12/site-packages/aiohttp/client.py", line 935, in _ws_connect
    resp = await self.request(
           ^^^^^^^^^^^^^^^^^^^
  File "/Users/tyson/my-discord-bot/venv/lib/python3.12/site-packages/aiohttp/client.py", line 661, in _request
    conn = await self._connector.connect(
           ^^^^^^^^^^^^^^^^^^^^^^^^^^^^^^
  File "/Users/tyson/my-discord-bot/venv/lib/python3.12/site-packages/aiohttp/connector.py", line 556, in connect
    proto = await self._create_connection(req, traces, timeout)
            ^^^^^^^^^^^^^^^^^^^^^^^^^^^^^^^^^^^^^^^^^^^^^^^^^^^
  File "/Users/tyson/my-discord-bot/venv/lib/python3.12/site-packages/aiohttp/connector.py", line 1009, in _create_connection
    _, proto = await self._create_direct_connection(req, traces, timeout)
               ^^^^^^^^^^^^^^^^^^^^^^^^^^^^^^^^^^^^^^^^^^^^^^^^^^^^^^^^^^
  File "/Users/tyson/my-discord-bot/venv/lib/python3.12/site-packages/aiohttp/connector.py", line 1300, in _create_direct_connection
    raise ClientConnectorError(req.connection_key, exc) from exc
aiohttp.client_exceptions.ClientConnectorError: Cannot connect to host gateway-us-east1-d.discord.gg:443 ssl:default [nodename nor servname provided, or not known]
[2024-10-08 21:50:33] [ERROR   ] discord.client: Attempting a reconnect in 6.21s
Traceback (most recent call last):
  File "/Users/tyson/my-discord-bot/venv/lib/python3.12/site-packages/aiohttp/connector.py", line 1294, in _create_direct_connection
    hosts = await self._resolve_host(host, port, traces=traces)
            ^^^^^^^^^^^^^^^^^^^^^^^^^^^^^^^^^^^^^^^^^^^^^^^^^^^
  File "/Users/tyson/my-discord-bot/venv/lib/python3.12/site-packages/aiohttp/connector.py", line 945, in _resolve_host
    return await asyncio.shield(resolved_host_task)
           ^^^^^^^^^^^^^^^^^^^^^^^^^^^^^^^^^^^^^^^^
  File "/Users/tyson/my-discord-bot/venv/lib/python3.12/site-packages/aiohttp/connector.py", line 982, in _resolve_host_with_throttle
    addrs = await self._resolver.resolve(host, port, family=self._family)
            ^^^^^^^^^^^^^^^^^^^^^^^^^^^^^^^^^^^^^^^^^^^^^^^^^^^^^^^^^^^^^
  File "/Users/tyson/my-discord-bot/venv/lib/python3.12/site-packages/aiohttp/resolver.py", line 38, in resolve
    infos = await self._loop.getaddrinfo(
            ^^^^^^^^^^^^^^^^^^^^^^^^^^^^^
  File "/Library/Frameworks/Python.framework/Versions/3.12/lib/python3.12/asyncio/base_events.py", line 878, in getaddrinfo
    return await self.run_in_executor(
           ^^^^^^^^^^^^^^^^^^^^^^^^^^^
  File "/Library/Frameworks/Python.framework/Versions/3.12/lib/python3.12/concurrent/futures/thread.py", line 58, in run
    result = self.fn(*self.args, **self.kwargs)
             ^^^^^^^^^^^^^^^^^^^^^^^^^^^^^^^^^^
  File "/Library/Frameworks/Python.framework/Versions/3.12/lib/python3.12/socket.py", line 963, in getaddrinfo
    for res in _socket.getaddrinfo(host, port, family, type, proto, flags):
               ^^^^^^^^^^^^^^^^^^^^^^^^^^^^^^^^^^^^^^^^^^^^^^^^^^^^^^^^^^^
socket.gaierror: [Errno 8] nodename nor servname provided, or not known

The above exception was the direct cause of the following exception:

Traceback (most recent call last):
  File "/Users/tyson/my-discord-bot/venv/lib/python3.12/site-packages/discord/client.py", line 664, in connect
    self.ws = await asyncio.wait_for(coro, timeout=60.0)
              ^^^^^^^^^^^^^^^^^^^^^^^^^^^^^^^^^^^^^^^^^^
  File "/Library/Frameworks/Python.framework/Versions/3.12/lib/python3.12/asyncio/tasks.py", line 510, in wait_for
    return await fut
           ^^^^^^^^^
  File "/Users/tyson/my-discord-bot/venv/lib/python3.12/site-packages/discord/gateway.py", line 374, in from_client
    socket = await client.http.ws_connect(str(url))
             ^^^^^^^^^^^^^^^^^^^^^^^^^^^^^^^^^^^^^^
  File "/Users/tyson/my-discord-bot/venv/lib/python3.12/site-packages/discord/http.py", line 550, in ws_connect
    return await self.__session.ws_connect(url, **kwargs)
           ^^^^^^^^^^^^^^^^^^^^^^^^^^^^^^^^^^^^^^^^^^^^^^
  File "/Users/tyson/my-discord-bot/venv/lib/python3.12/site-packages/aiohttp/client.py", line 935, in _ws_connect
    resp = await self.request(
           ^^^^^^^^^^^^^^^^^^^
  File "/Users/tyson/my-discord-bot/venv/lib/python3.12/site-packages/aiohttp/client.py", line 661, in _request
    conn = await self._connector.connect(
           ^^^^^^^^^^^^^^^^^^^^^^^^^^^^^^
  File "/Users/tyson/my-discord-bot/venv/lib/python3.12/site-packages/aiohttp/connector.py", line 556, in connect
    proto = await self._create_connection(req, traces, timeout)
            ^^^^^^^^^^^^^^^^^^^^^^^^^^^^^^^^^^^^^^^^^^^^^^^^^^^
  File "/Users/tyson/my-discord-bot/venv/lib/python3.12/site-packages/aiohttp/connector.py", line 1009, in _create_connection
    _, proto = await self._create_direct_connection(req, traces, timeout)
               ^^^^^^^^^^^^^^^^^^^^^^^^^^^^^^^^^^^^^^^^^^^^^^^^^^^^^^^^^^
  File "/Users/tyson/my-discord-bot/venv/lib/python3.12/site-packages/aiohttp/connector.py", line 1300, in _create_direct_connection
    raise ClientConnectorError(req.connection_key, exc) from exc
aiohttp.client_exceptions.ClientConnectorError: Cannot connect to host gateway-us-east1-d.discord.gg:443 ssl:default [nodename nor servname provided, or not known]
[2024-10-08 21:57:41] [ERROR   ] discord.client: Attempting a reconnect in 15.17s
Traceback (most recent call last):
  File "/Users/tyson/my-discord-bot/venv/lib/python3.12/site-packages/aiohttp/connector.py", line 1294, in _create_direct_connection
    hosts = await self._resolve_host(host, port, traces=traces)
            ^^^^^^^^^^^^^^^^^^^^^^^^^^^^^^^^^^^^^^^^^^^^^^^^^^^
  File "/Users/tyson/my-discord-bot/venv/lib/python3.12/site-packages/aiohttp/connector.py", line 945, in _resolve_host
    return await asyncio.shield(resolved_host_task)
           ^^^^^^^^^^^^^^^^^^^^^^^^^^^^^^^^^^^^^^^^
  File "/Users/tyson/my-discord-bot/venv/lib/python3.12/site-packages/aiohttp/connector.py", line 982, in _resolve_host_with_throttle
    addrs = await self._resolver.resolve(host, port, family=self._family)
            ^^^^^^^^^^^^^^^^^^^^^^^^^^^^^^^^^^^^^^^^^^^^^^^^^^^^^^^^^^^^^
  File "/Users/tyson/my-discord-bot/venv/lib/python3.12/site-packages/aiohttp/resolver.py", line 38, in resolve
    infos = await self._loop.getaddrinfo(
            ^^^^^^^^^^^^^^^^^^^^^^^^^^^^^
  File "/Library/Frameworks/Python.framework/Versions/3.12/lib/python3.12/asyncio/base_events.py", line 878, in getaddrinfo
    return await self.run_in_executor(
           ^^^^^^^^^^^^^^^^^^^^^^^^^^^
  File "/Library/Frameworks/Python.framework/Versions/3.12/lib/python3.12/concurrent/futures/thread.py", line 58, in run
    result = self.fn(*self.args, **self.kwargs)
             ^^^^^^^^^^^^^^^^^^^^^^^^^^^^^^^^^^
  File "/Library/Frameworks/Python.framework/Versions/3.12/lib/python3.12/socket.py", line 963, in getaddrinfo
    for res in _socket.getaddrinfo(host, port, family, type, proto, flags):
               ^^^^^^^^^^^^^^^^^^^^^^^^^^^^^^^^^^^^^^^^^^^^^^^^^^^^^^^^^^^
socket.gaierror: [Errno 8] nodename nor servname provided, or not known

The above exception was the direct cause of the following exception:

Traceback (most recent call last):
  File "/Users/tyson/my-discord-bot/venv/lib/python3.12/site-packages/discord/client.py", line 664, in connect
    self.ws = await asyncio.wait_for(coro, timeout=60.0)
              ^^^^^^^^^^^^^^^^^^^^^^^^^^^^^^^^^^^^^^^^^^
  File "/Library/Frameworks/Python.framework/Versions/3.12/lib/python3.12/asyncio/tasks.py", line 510, in wait_for
    return await fut
           ^^^^^^^^^
  File "/Users/tyson/my-discord-bot/venv/lib/python3.12/site-packages/discord/gateway.py", line 374, in from_client
    socket = await client.http.ws_connect(str(url))
             ^^^^^^^^^^^^^^^^^^^^^^^^^^^^^^^^^^^^^^
  File "/Users/tyson/my-discord-bot/venv/lib/python3.12/site-packages/discord/http.py", line 550, in ws_connect
    return await self.__session.ws_connect(url, **kwargs)
           ^^^^^^^^^^^^^^^^^^^^^^^^^^^^^^^^^^^^^^^^^^^^^^
  File "/Users/tyson/my-discord-bot/venv/lib/python3.12/site-packages/aiohttp/client.py", line 935, in _ws_connect
    resp = await self.request(
           ^^^^^^^^^^^^^^^^^^^
  File "/Users/tyson/my-discord-bot/venv/lib/python3.12/site-packages/aiohttp/client.py", line 661, in _request
    conn = await self._connector.connect(
           ^^^^^^^^^^^^^^^^^^^^^^^^^^^^^^
  File "/Users/tyson/my-discord-bot/venv/lib/python3.12/site-packages/aiohttp/connector.py", line 556, in connect
    proto = await self._create_connection(req, traces, timeout)
            ^^^^^^^^^^^^^^^^^^^^^^^^^^^^^^^^^^^^^^^^^^^^^^^^^^^
  File "/Users/tyson/my-discord-bot/venv/lib/python3.12/site-packages/aiohttp/connector.py", line 1009, in _create_connection
    _, proto = await self._create_direct_connection(req, traces, timeout)
               ^^^^^^^^^^^^^^^^^^^^^^^^^^^^^^^^^^^^^^^^^^^^^^^^^^^^^^^^^^
  File "/Users/tyson/my-discord-bot/venv/lib/python3.12/site-packages/aiohttp/connector.py", line 1300, in _create_direct_connection
    raise ClientConnectorError(req.connection_key, exc) from exc
aiohttp.client_exceptions.ClientConnectorError: Cannot connect to host gateway-us-east1-d.discord.gg:443 ssl:default [nodename nor servname provided, or not known]
[2024-10-08 22:15:42] [INFO    ] discord.gateway: Shard ID None session has been invalidated.
[2024-10-08 22:32:20] [INFO    ] discord.gateway: Shard ID None session has been invalidated.
[2024-10-08 22:45:54] [INFO    ] discord.gateway: Shard ID None session has been invalidated.
[2024-10-08 22:46:00] [INFO    ] discord.gateway: Shard ID None has connected to Gateway (Session ID: c5e9f7942dc72955bc7b773545b7983a).
[2024-10-08 23:23:38] [INFO    ] discord.gateway: Shard ID None has successfully RESUMED session c5e9f7942dc72955bc7b773545b7983a.
[2024-10-09 01:32:05] [INFO    ] discord.gateway: Shard ID None has successfully RESUMED session c5e9f7942dc72955bc7b773545b7983a.
[2024-10-09 01:41:14] [WARNING ] discord.gateway: Can't keep up, shard ID None websocket is 35.8s behind.
[2024-10-09 01:46:42] [INFO    ] discord.gateway: Shard ID None session has been invalidated.
[2024-10-09 01:46:48] [INFO    ] discord.gateway: Shard ID None has connected to Gateway (Session ID: 0608c898a938420d67cae299caa321a3).
[2024-10-09 02:03:35] [INFO    ] discord.gateway: Shard ID None session has been invalidated.
[2024-10-09 02:03:41] [INFO    ] discord.gateway: Shard ID None has connected to Gateway (Session ID: 58562b8147a72d92c27ee105f6df6597).
[2024-10-09 02:57:33] [INFO    ] discord.gateway: Shard ID None session has been invalidated.
[2024-10-09 02:57:39] [INFO    ] discord.gateway: Shard ID None has connected to Gateway (Session ID: 9462921fba69d6ddba641214a9eed642).
[2024-10-09 03:27:33] [INFO    ] discord.gateway: Shard ID None has successfully RESUMED session 9462921fba69d6ddba641214a9eed642.
[2024-10-09 03:55:45] [INFO    ] discord.gateway: Shard ID None has successfully RESUMED session 9462921fba69d6ddba641214a9eed642.
[2024-10-09 04:34:50] [INFO    ] discord.gateway: Shard ID None session has been invalidated.
[2024-10-09 04:34:56] [INFO    ] discord.gateway: Shard ID None has connected to Gateway (Session ID: 50e1627fe9b180aa0dee065b6c68f0d2).
[2024-10-09 05:10:38] [INFO    ] discord.gateway: Shard ID None has successfully RESUMED session 50e1627fe9b180aa0dee065b6c68f0d2.
[2024-10-09 05:47:26] [INFO    ] discord.gateway: Shard ID None has successfully RESUMED session 50e1627fe9b180aa0dee065b6c68f0d2.
[2024-10-09 07:35:41] [INFO    ] discord.gateway: Shard ID None has successfully RESUMED session 50e1627fe9b180aa0dee065b6c68f0d2.
[2024-10-09 08:48:23] [ERROR   ] discord.client: Attempting a reconnect in 0.96s
Traceback (most recent call last):
  File "/Users/tyson/my-discord-bot/venv/lib/python3.12/site-packages/aiohttp/connector.py", line 1294, in _create_direct_connection
    hosts = await self._resolve_host(host, port, traces=traces)
            ^^^^^^^^^^^^^^^^^^^^^^^^^^^^^^^^^^^^^^^^^^^^^^^^^^^
  File "/Users/tyson/my-discord-bot/venv/lib/python3.12/site-packages/aiohttp/connector.py", line 945, in _resolve_host
    return await asyncio.shield(resolved_host_task)
           ^^^^^^^^^^^^^^^^^^^^^^^^^^^^^^^^^^^^^^^^
  File "/Users/tyson/my-discord-bot/venv/lib/python3.12/site-packages/aiohttp/connector.py", line 982, in _resolve_host_with_throttle
    addrs = await self._resolver.resolve(host, port, family=self._family)
            ^^^^^^^^^^^^^^^^^^^^^^^^^^^^^^^^^^^^^^^^^^^^^^^^^^^^^^^^^^^^^
  File "/Users/tyson/my-discord-bot/venv/lib/python3.12/site-packages/aiohttp/resolver.py", line 38, in resolve
    infos = await self._loop.getaddrinfo(
            ^^^^^^^^^^^^^^^^^^^^^^^^^^^^^
  File "/Library/Frameworks/Python.framework/Versions/3.12/lib/python3.12/asyncio/base_events.py", line 878, in getaddrinfo
    return await self.run_in_executor(
           ^^^^^^^^^^^^^^^^^^^^^^^^^^^
  File "/Library/Frameworks/Python.framework/Versions/3.12/lib/python3.12/concurrent/futures/thread.py", line 58, in run
    result = self.fn(*self.args, **self.kwargs)
             ^^^^^^^^^^^^^^^^^^^^^^^^^^^^^^^^^^
  File "/Library/Frameworks/Python.framework/Versions/3.12/lib/python3.12/socket.py", line 963, in getaddrinfo
    for res in _socket.getaddrinfo(host, port, family, type, proto, flags):
               ^^^^^^^^^^^^^^^^^^^^^^^^^^^^^^^^^^^^^^^^^^^^^^^^^^^^^^^^^^^
socket.gaierror: [Errno 8] nodename nor servname provided, or not known

The above exception was the direct cause of the following exception:

Traceback (most recent call last):
  File "/Users/tyson/my-discord-bot/venv/lib/python3.12/site-packages/discord/client.py", line 664, in connect
    self.ws = await asyncio.wait_for(coro, timeout=60.0)
              ^^^^^^^^^^^^^^^^^^^^^^^^^^^^^^^^^^^^^^^^^^
  File "/Library/Frameworks/Python.framework/Versions/3.12/lib/python3.12/asyncio/tasks.py", line 510, in wait_for
    return await fut
           ^^^^^^^^^
  File "/Users/tyson/my-discord-bot/venv/lib/python3.12/site-packages/discord/gateway.py", line 374, in from_client
    socket = await client.http.ws_connect(str(url))
             ^^^^^^^^^^^^^^^^^^^^^^^^^^^^^^^^^^^^^^
  File "/Users/tyson/my-discord-bot/venv/lib/python3.12/site-packages/discord/http.py", line 550, in ws_connect
    return await self.__session.ws_connect(url, **kwargs)
           ^^^^^^^^^^^^^^^^^^^^^^^^^^^^^^^^^^^^^^^^^^^^^^
  File "/Users/tyson/my-discord-bot/venv/lib/python3.12/site-packages/aiohttp/client.py", line 935, in _ws_connect
    resp = await self.request(
           ^^^^^^^^^^^^^^^^^^^
  File "/Users/tyson/my-discord-bot/venv/lib/python3.12/site-packages/aiohttp/client.py", line 661, in _request
    conn = await self._connector.connect(
           ^^^^^^^^^^^^^^^^^^^^^^^^^^^^^^
  File "/Users/tyson/my-discord-bot/venv/lib/python3.12/site-packages/aiohttp/connector.py", line 556, in connect
    proto = await self._create_connection(req, traces, timeout)
            ^^^^^^^^^^^^^^^^^^^^^^^^^^^^^^^^^^^^^^^^^^^^^^^^^^^
  File "/Users/tyson/my-discord-bot/venv/lib/python3.12/site-packages/aiohttp/connector.py", line 1009, in _create_connection
    _, proto = await self._create_direct_connection(req, traces, timeout)
               ^^^^^^^^^^^^^^^^^^^^^^^^^^^^^^^^^^^^^^^^^^^^^^^^^^^^^^^^^^
  File "/Users/tyson/my-discord-bot/venv/lib/python3.12/site-packages/aiohttp/connector.py", line 1300, in _create_direct_connection
    raise ClientConnectorError(req.connection_key, exc) from exc
aiohttp.client_exceptions.ClientConnectorError: Cannot connect to host gateway-us-east1-d.discord.gg:443 ssl:default [nodename nor servname provided, or not known]
[2024-10-09 08:48:24] [ERROR   ] discord.client: Attempting a reconnect in 3.93s
Traceback (most recent call last):
  File "/Users/tyson/my-discord-bot/venv/lib/python3.12/site-packages/aiohttp/connector.py", line 1294, in _create_direct_connection
    hosts = await self._resolve_host(host, port, traces=traces)
            ^^^^^^^^^^^^^^^^^^^^^^^^^^^^^^^^^^^^^^^^^^^^^^^^^^^
  File "/Users/tyson/my-discord-bot/venv/lib/python3.12/site-packages/aiohttp/connector.py", line 945, in _resolve_host
    return await asyncio.shield(resolved_host_task)
           ^^^^^^^^^^^^^^^^^^^^^^^^^^^^^^^^^^^^^^^^
  File "/Users/tyson/my-discord-bot/venv/lib/python3.12/site-packages/aiohttp/connector.py", line 982, in _resolve_host_with_throttle
    addrs = await self._resolver.resolve(host, port, family=self._family)
            ^^^^^^^^^^^^^^^^^^^^^^^^^^^^^^^^^^^^^^^^^^^^^^^^^^^^^^^^^^^^^
  File "/Users/tyson/my-discord-bot/venv/lib/python3.12/site-packages/aiohttp/resolver.py", line 38, in resolve
    infos = await self._loop.getaddrinfo(
            ^^^^^^^^^^^^^^^^^^^^^^^^^^^^^
  File "/Library/Frameworks/Python.framework/Versions/3.12/lib/python3.12/asyncio/base_events.py", line 878, in getaddrinfo
    return await self.run_in_executor(
           ^^^^^^^^^^^^^^^^^^^^^^^^^^^
  File "/Library/Frameworks/Python.framework/Versions/3.12/lib/python3.12/concurrent/futures/thread.py", line 58, in run
    result = self.fn(*self.args, **self.kwargs)
             ^^^^^^^^^^^^^^^^^^^^^^^^^^^^^^^^^^
  File "/Library/Frameworks/Python.framework/Versions/3.12/lib/python3.12/socket.py", line 963, in getaddrinfo
    for res in _socket.getaddrinfo(host, port, family, type, proto, flags):
               ^^^^^^^^^^^^^^^^^^^^^^^^^^^^^^^^^^^^^^^^^^^^^^^^^^^^^^^^^^^
socket.gaierror: [Errno 8] nodename nor servname provided, or not known

The above exception was the direct cause of the following exception:

Traceback (most recent call last):
  File "/Users/tyson/my-discord-bot/venv/lib/python3.12/site-packages/discord/client.py", line 664, in connect
    self.ws = await asyncio.wait_for(coro, timeout=60.0)
              ^^^^^^^^^^^^^^^^^^^^^^^^^^^^^^^^^^^^^^^^^^
  File "/Library/Frameworks/Python.framework/Versions/3.12/lib/python3.12/asyncio/tasks.py", line 510, in wait_for
    return await fut
           ^^^^^^^^^
  File "/Users/tyson/my-discord-bot/venv/lib/python3.12/site-packages/discord/gateway.py", line 374, in from_client
    socket = await client.http.ws_connect(str(url))
             ^^^^^^^^^^^^^^^^^^^^^^^^^^^^^^^^^^^^^^
  File "/Users/tyson/my-discord-bot/venv/lib/python3.12/site-packages/discord/http.py", line 550, in ws_connect
    return await self.__session.ws_connect(url, **kwargs)
           ^^^^^^^^^^^^^^^^^^^^^^^^^^^^^^^^^^^^^^^^^^^^^^
  File "/Users/tyson/my-discord-bot/venv/lib/python3.12/site-packages/aiohttp/client.py", line 935, in _ws_connect
    resp = await self.request(
           ^^^^^^^^^^^^^^^^^^^
  File "/Users/tyson/my-discord-bot/venv/lib/python3.12/site-packages/aiohttp/client.py", line 661, in _request
    conn = await self._connector.connect(
           ^^^^^^^^^^^^^^^^^^^^^^^^^^^^^^
  File "/Users/tyson/my-discord-bot/venv/lib/python3.12/site-packages/aiohttp/connector.py", line 556, in connect
    proto = await self._create_connection(req, traces, timeout)
            ^^^^^^^^^^^^^^^^^^^^^^^^^^^^^^^^^^^^^^^^^^^^^^^^^^^
  File "/Users/tyson/my-discord-bot/venv/lib/python3.12/site-packages/aiohttp/connector.py", line 1009, in _create_connection
    _, proto = await self._create_direct_connection(req, traces, timeout)
               ^^^^^^^^^^^^^^^^^^^^^^^^^^^^^^^^^^^^^^^^^^^^^^^^^^^^^^^^^^
  File "/Users/tyson/my-discord-bot/venv/lib/python3.12/site-packages/aiohttp/connector.py", line 1300, in _create_direct_connection
    raise ClientConnectorError(req.connection_key, exc) from exc
aiohttp.client_exceptions.ClientConnectorError: Cannot connect to host gateway-us-east1-d.discord.gg:443 ssl:default [nodename nor servname provided, or not known]
[2024-10-09 08:48:28] [ERROR   ] discord.client: Attempting a reconnect in 3.48s
Traceback (most recent call last):
  File "/Users/tyson/my-discord-bot/venv/lib/python3.12/site-packages/aiohttp/connector.py", line 1294, in _create_direct_connection
    hosts = await self._resolve_host(host, port, traces=traces)
            ^^^^^^^^^^^^^^^^^^^^^^^^^^^^^^^^^^^^^^^^^^^^^^^^^^^
  File "/Users/tyson/my-discord-bot/venv/lib/python3.12/site-packages/aiohttp/connector.py", line 945, in _resolve_host
    return await asyncio.shield(resolved_host_task)
           ^^^^^^^^^^^^^^^^^^^^^^^^^^^^^^^^^^^^^^^^
  File "/Users/tyson/my-discord-bot/venv/lib/python3.12/site-packages/aiohttp/connector.py", line 982, in _resolve_host_with_throttle
    addrs = await self._resolver.resolve(host, port, family=self._family)
            ^^^^^^^^^^^^^^^^^^^^^^^^^^^^^^^^^^^^^^^^^^^^^^^^^^^^^^^^^^^^^
  File "/Users/tyson/my-discord-bot/venv/lib/python3.12/site-packages/aiohttp/resolver.py", line 38, in resolve
    infos = await self._loop.getaddrinfo(
            ^^^^^^^^^^^^^^^^^^^^^^^^^^^^^
  File "/Library/Frameworks/Python.framework/Versions/3.12/lib/python3.12/asyncio/base_events.py", line 878, in getaddrinfo
    return await self.run_in_executor(
           ^^^^^^^^^^^^^^^^^^^^^^^^^^^
  File "/Library/Frameworks/Python.framework/Versions/3.12/lib/python3.12/concurrent/futures/thread.py", line 58, in run
    result = self.fn(*self.args, **self.kwargs)
             ^^^^^^^^^^^^^^^^^^^^^^^^^^^^^^^^^^
  File "/Library/Frameworks/Python.framework/Versions/3.12/lib/python3.12/socket.py", line 963, in getaddrinfo
    for res in _socket.getaddrinfo(host, port, family, type, proto, flags):
               ^^^^^^^^^^^^^^^^^^^^^^^^^^^^^^^^^^^^^^^^^^^^^^^^^^^^^^^^^^^
socket.gaierror: [Errno 8] nodename nor servname provided, or not known

The above exception was the direct cause of the following exception:

Traceback (most recent call last):
  File "/Users/tyson/my-discord-bot/venv/lib/python3.12/site-packages/discord/client.py", line 664, in connect
    self.ws = await asyncio.wait_for(coro, timeout=60.0)
              ^^^^^^^^^^^^^^^^^^^^^^^^^^^^^^^^^^^^^^^^^^
  File "/Library/Frameworks/Python.framework/Versions/3.12/lib/python3.12/asyncio/tasks.py", line 510, in wait_for
    return await fut
           ^^^^^^^^^
  File "/Users/tyson/my-discord-bot/venv/lib/python3.12/site-packages/discord/gateway.py", line 374, in from_client
    socket = await client.http.ws_connect(str(url))
             ^^^^^^^^^^^^^^^^^^^^^^^^^^^^^^^^^^^^^^
  File "/Users/tyson/my-discord-bot/venv/lib/python3.12/site-packages/discord/http.py", line 550, in ws_connect
    return await self.__session.ws_connect(url, **kwargs)
           ^^^^^^^^^^^^^^^^^^^^^^^^^^^^^^^^^^^^^^^^^^^^^^
  File "/Users/tyson/my-discord-bot/venv/lib/python3.12/site-packages/aiohttp/client.py", line 935, in _ws_connect
    resp = await self.request(
           ^^^^^^^^^^^^^^^^^^^
  File "/Users/tyson/my-discord-bot/venv/lib/python3.12/site-packages/aiohttp/client.py", line 661, in _request
    conn = await self._connector.connect(
           ^^^^^^^^^^^^^^^^^^^^^^^^^^^^^^
  File "/Users/tyson/my-discord-bot/venv/lib/python3.12/site-packages/aiohttp/connector.py", line 556, in connect
    proto = await self._create_connection(req, traces, timeout)
            ^^^^^^^^^^^^^^^^^^^^^^^^^^^^^^^^^^^^^^^^^^^^^^^^^^^
  File "/Users/tyson/my-discord-bot/venv/lib/python3.12/site-packages/aiohttp/connector.py", line 1009, in _create_connection
    _, proto = await self._create_direct_connection(req, traces, timeout)
               ^^^^^^^^^^^^^^^^^^^^^^^^^^^^^^^^^^^^^^^^^^^^^^^^^^^^^^^^^^
  File "/Users/tyson/my-discord-bot/venv/lib/python3.12/site-packages/aiohttp/connector.py", line 1300, in _create_direct_connection
    raise ClientConnectorError(req.connection_key, exc) from exc
aiohttp.client_exceptions.ClientConnectorError: Cannot connect to host gateway-us-east1-d.discord.gg:443 ssl:default [nodename nor servname provided, or not known]
[2024-10-09 08:49:23] [ERROR   ] discord.client: Attempting a reconnect in 6.29s
Traceback (most recent call last):
  File "/Users/tyson/my-discord-bot/venv/lib/python3.12/site-packages/aiohttp/connector.py", line 1294, in _create_direct_connection
    hosts = await self._resolve_host(host, port, traces=traces)
            ^^^^^^^^^^^^^^^^^^^^^^^^^^^^^^^^^^^^^^^^^^^^^^^^^^^
  File "/Users/tyson/my-discord-bot/venv/lib/python3.12/site-packages/aiohttp/connector.py", line 945, in _resolve_host
    return await asyncio.shield(resolved_host_task)
           ^^^^^^^^^^^^^^^^^^^^^^^^^^^^^^^^^^^^^^^^
  File "/Users/tyson/my-discord-bot/venv/lib/python3.12/site-packages/aiohttp/connector.py", line 982, in _resolve_host_with_throttle
    addrs = await self._resolver.resolve(host, port, family=self._family)
            ^^^^^^^^^^^^^^^^^^^^^^^^^^^^^^^^^^^^^^^^^^^^^^^^^^^^^^^^^^^^^
  File "/Users/tyson/my-discord-bot/venv/lib/python3.12/site-packages/aiohttp/resolver.py", line 38, in resolve
    infos = await self._loop.getaddrinfo(
            ^^^^^^^^^^^^^^^^^^^^^^^^^^^^^
  File "/Library/Frameworks/Python.framework/Versions/3.12/lib/python3.12/asyncio/base_events.py", line 878, in getaddrinfo
    return await self.run_in_executor(
           ^^^^^^^^^^^^^^^^^^^^^^^^^^^
  File "/Library/Frameworks/Python.framework/Versions/3.12/lib/python3.12/concurrent/futures/thread.py", line 58, in run
    result = self.fn(*self.args, **self.kwargs)
             ^^^^^^^^^^^^^^^^^^^^^^^^^^^^^^^^^^
  File "/Library/Frameworks/Python.framework/Versions/3.12/lib/python3.12/socket.py", line 963, in getaddrinfo
    for res in _socket.getaddrinfo(host, port, family, type, proto, flags):
               ^^^^^^^^^^^^^^^^^^^^^^^^^^^^^^^^^^^^^^^^^^^^^^^^^^^^^^^^^^^
socket.gaierror: [Errno 8] nodename nor servname provided, or not known

The above exception was the direct cause of the following exception:

Traceback (most recent call last):
  File "/Users/tyson/my-discord-bot/venv/lib/python3.12/site-packages/discord/client.py", line 664, in connect
    self.ws = await asyncio.wait_for(coro, timeout=60.0)
              ^^^^^^^^^^^^^^^^^^^^^^^^^^^^^^^^^^^^^^^^^^
  File "/Library/Frameworks/Python.framework/Versions/3.12/lib/python3.12/asyncio/tasks.py", line 510, in wait_for
    return await fut
           ^^^^^^^^^
  File "/Users/tyson/my-discord-bot/venv/lib/python3.12/site-packages/discord/gateway.py", line 374, in from_client
    socket = await client.http.ws_connect(str(url))
             ^^^^^^^^^^^^^^^^^^^^^^^^^^^^^^^^^^^^^^
  File "/Users/tyson/my-discord-bot/venv/lib/python3.12/site-packages/discord/http.py", line 550, in ws_connect
    return await self.__session.ws_connect(url, **kwargs)
           ^^^^^^^^^^^^^^^^^^^^^^^^^^^^^^^^^^^^^^^^^^^^^^
  File "/Users/tyson/my-discord-bot/venv/lib/python3.12/site-packages/aiohttp/client.py", line 935, in _ws_connect
    resp = await self.request(
           ^^^^^^^^^^^^^^^^^^^
  File "/Users/tyson/my-discord-bot/venv/lib/python3.12/site-packages/aiohttp/client.py", line 661, in _request
    conn = await self._connector.connect(
           ^^^^^^^^^^^^^^^^^^^^^^^^^^^^^^
  File "/Users/tyson/my-discord-bot/venv/lib/python3.12/site-packages/aiohttp/connector.py", line 556, in connect
    proto = await self._create_connection(req, traces, timeout)
            ^^^^^^^^^^^^^^^^^^^^^^^^^^^^^^^^^^^^^^^^^^^^^^^^^^^
  File "/Users/tyson/my-discord-bot/venv/lib/python3.12/site-packages/aiohttp/connector.py", line 1009, in _create_connection
    _, proto = await self._create_direct_connection(req, traces, timeout)
               ^^^^^^^^^^^^^^^^^^^^^^^^^^^^^^^^^^^^^^^^^^^^^^^^^^^^^^^^^^
  File "/Users/tyson/my-discord-bot/venv/lib/python3.12/site-packages/aiohttp/connector.py", line 1300, in _create_direct_connection
    raise ClientConnectorError(req.connection_key, exc) from exc
aiohttp.client_exceptions.ClientConnectorError: Cannot connect to host gateway-us-east1-d.discord.gg:443 ssl:default [nodename nor servname provided, or not known]
[2024-10-09 08:50:24] [ERROR   ] discord.client: Attempting a reconnect in 31.27s
Traceback (most recent call last):
  File "/Users/tyson/my-discord-bot/venv/lib/python3.12/site-packages/aiohttp/connector.py", line 1294, in _create_direct_connection
    hosts = await self._resolve_host(host, port, traces=traces)
            ^^^^^^^^^^^^^^^^^^^^^^^^^^^^^^^^^^^^^^^^^^^^^^^^^^^
  File "/Users/tyson/my-discord-bot/venv/lib/python3.12/site-packages/aiohttp/connector.py", line 945, in _resolve_host
    return await asyncio.shield(resolved_host_task)
           ^^^^^^^^^^^^^^^^^^^^^^^^^^^^^^^^^^^^^^^^
  File "/Users/tyson/my-discord-bot/venv/lib/python3.12/site-packages/aiohttp/connector.py", line 982, in _resolve_host_with_throttle
    addrs = await self._resolver.resolve(host, port, family=self._family)
            ^^^^^^^^^^^^^^^^^^^^^^^^^^^^^^^^^^^^^^^^^^^^^^^^^^^^^^^^^^^^^
  File "/Users/tyson/my-discord-bot/venv/lib/python3.12/site-packages/aiohttp/resolver.py", line 38, in resolve
    infos = await self._loop.getaddrinfo(
            ^^^^^^^^^^^^^^^^^^^^^^^^^^^^^
  File "/Library/Frameworks/Python.framework/Versions/3.12/lib/python3.12/asyncio/base_events.py", line 878, in getaddrinfo
    return await self.run_in_executor(
           ^^^^^^^^^^^^^^^^^^^^^^^^^^^
  File "/Library/Frameworks/Python.framework/Versions/3.12/lib/python3.12/concurrent/futures/thread.py", line 58, in run
    result = self.fn(*self.args, **self.kwargs)
             ^^^^^^^^^^^^^^^^^^^^^^^^^^^^^^^^^^
  File "/Library/Frameworks/Python.framework/Versions/3.12/lib/python3.12/socket.py", line 963, in getaddrinfo
    for res in _socket.getaddrinfo(host, port, family, type, proto, flags):
               ^^^^^^^^^^^^^^^^^^^^^^^^^^^^^^^^^^^^^^^^^^^^^^^^^^^^^^^^^^^
socket.gaierror: [Errno 8] nodename nor servname provided, or not known

The above exception was the direct cause of the following exception:

Traceback (most recent call last):
  File "/Users/tyson/my-discord-bot/venv/lib/python3.12/site-packages/discord/client.py", line 664, in connect
    self.ws = await asyncio.wait_for(coro, timeout=60.0)
              ^^^^^^^^^^^^^^^^^^^^^^^^^^^^^^^^^^^^^^^^^^
  File "/Library/Frameworks/Python.framework/Versions/3.12/lib/python3.12/asyncio/tasks.py", line 510, in wait_for
    return await fut
           ^^^^^^^^^
  File "/Users/tyson/my-discord-bot/venv/lib/python3.12/site-packages/discord/gateway.py", line 374, in from_client
    socket = await client.http.ws_connect(str(url))
             ^^^^^^^^^^^^^^^^^^^^^^^^^^^^^^^^^^^^^^
  File "/Users/tyson/my-discord-bot/venv/lib/python3.12/site-packages/discord/http.py", line 550, in ws_connect
    return await self.__session.ws_connect(url, **kwargs)
           ^^^^^^^^^^^^^^^^^^^^^^^^^^^^^^^^^^^^^^^^^^^^^^
  File "/Users/tyson/my-discord-bot/venv/lib/python3.12/site-packages/aiohttp/client.py", line 935, in _ws_connect
    resp = await self.request(
           ^^^^^^^^^^^^^^^^^^^
  File "/Users/tyson/my-discord-bot/venv/lib/python3.12/site-packages/aiohttp/client.py", line 661, in _request
    conn = await self._connector.connect(
           ^^^^^^^^^^^^^^^^^^^^^^^^^^^^^^
  File "/Users/tyson/my-discord-bot/venv/lib/python3.12/site-packages/aiohttp/connector.py", line 556, in connect
    proto = await self._create_connection(req, traces, timeout)
            ^^^^^^^^^^^^^^^^^^^^^^^^^^^^^^^^^^^^^^^^^^^^^^^^^^^
  File "/Users/tyson/my-discord-bot/venv/lib/python3.12/site-packages/aiohttp/connector.py", line 1009, in _create_connection
    _, proto = await self._create_direct_connection(req, traces, timeout)
               ^^^^^^^^^^^^^^^^^^^^^^^^^^^^^^^^^^^^^^^^^^^^^^^^^^^^^^^^^^
  File "/Users/tyson/my-discord-bot/venv/lib/python3.12/site-packages/aiohttp/connector.py", line 1300, in _create_direct_connection
    raise ClientConnectorError(req.connection_key, exc) from exc
aiohttp.client_exceptions.ClientConnectorError: Cannot connect to host gateway-us-east1-d.discord.gg:443 ssl:default [nodename nor servname provided, or not known]
[2024-10-09 09:46:04] [INFO    ] discord.gateway: Shard ID None session has been invalidated.
[2024-10-09 10:16:42] [INFO    ] discord.gateway: Shard ID None has connected to Gateway (Session ID: 608ccbe8a44a00046c3fb6f2079339e8).
[2024-10-09 11:29:50] [INFO    ] discord.gateway: Shard ID None session has been invalidated.
[2024-10-09 11:56:56] [INFO    ] discord.gateway: Shard ID None session has been invalidated.
[2024-10-09 11:57:02] [INFO    ] discord.gateway: Shard ID None has connected to Gateway (Session ID: 590ff8024af2ae43b4b82080f40333b1).
[2024-10-09 12:40:23] [INFO    ] discord.gateway: Shard ID None session has been invalidated.
[2024-10-09 12:40:30] [INFO    ] discord.gateway: Shard ID None has connected to Gateway (Session ID: 54f98b54f27880571231a76eb8bb7228).
[2024-10-09 13:13:23] [INFO    ] discord.gateway: Shard ID None session has been invalidated.
[2024-10-09 13:13:29] [INFO    ] discord.gateway: Shard ID None has connected to Gateway (Session ID: d8a66d47cbe7c0462fbadc043f71f594).
[2024-10-09 13:17:41] [INFO    ] discord.gateway: Shard ID None session has been invalidated.
[2024-10-09 13:17:47] [INFO    ] discord.gateway: Shard ID None has connected to Gateway (Session ID: 88d465734d2c30a5bd841b77c45dfea1).
[2024-10-09 13:20:27] [INFO    ] discord.gateway: Shard ID None session has been invalidated.
[2024-10-09 13:20:33] [INFO    ] discord.gateway: Shard ID None has connected to Gateway (Session ID: 5c838ce2978491b1fae473a4ef50cd0d).
[2024-10-09 13:37:22] [INFO    ] discord.gateway: Shard ID None session has been invalidated.
[2024-10-09 13:37:28] [INFO    ] discord.gateway: Shard ID None has connected to Gateway (Session ID: a0aa65e3061b1699977394be223fcb86).
[2024-10-09 15:33:13] [INFO    ] discord.gateway: Shard ID None has successfully RESUMED session a0aa65e3061b1699977394be223fcb86.
[2024-10-09 18:51:27] [INFO    ] discord.gateway: Shard ID None has successfully RESUMED session a0aa65e3061b1699977394be223fcb86.
[2024-10-09 19:10:41] [INFO    ] discord.gateway: Shard ID None has successfully RESUMED session a0aa65e3061b1699977394be223fcb86.
[2024-10-09 19:16:53] [INFO    ] discord.gateway: Shard ID None has successfully RESUMED session a0aa65e3061b1699977394be223fcb86.
[2024-10-09 21:16:37] [INFO    ] discord.gateway: Shard ID None has successfully RESUMED session a0aa65e3061b1699977394be223fcb86.
[2024-10-09 21:36:11] [ERROR   ] discord.client: Attempting a reconnect in 0.32s
Traceback (most recent call last):
  File "/Users/tyson/my-discord-bot/venv/lib/python3.12/site-packages/aiohttp/connector.py", line 1294, in _create_direct_connection
    hosts = await self._resolve_host(host, port, traces=traces)
            ^^^^^^^^^^^^^^^^^^^^^^^^^^^^^^^^^^^^^^^^^^^^^^^^^^^
  File "/Users/tyson/my-discord-bot/venv/lib/python3.12/site-packages/aiohttp/connector.py", line 945, in _resolve_host
    return await asyncio.shield(resolved_host_task)
           ^^^^^^^^^^^^^^^^^^^^^^^^^^^^^^^^^^^^^^^^
  File "/Users/tyson/my-discord-bot/venv/lib/python3.12/site-packages/aiohttp/connector.py", line 982, in _resolve_host_with_throttle
    addrs = await self._resolver.resolve(host, port, family=self._family)
            ^^^^^^^^^^^^^^^^^^^^^^^^^^^^^^^^^^^^^^^^^^^^^^^^^^^^^^^^^^^^^
  File "/Users/tyson/my-discord-bot/venv/lib/python3.12/site-packages/aiohttp/resolver.py", line 38, in resolve
    infos = await self._loop.getaddrinfo(
            ^^^^^^^^^^^^^^^^^^^^^^^^^^^^^
  File "/Library/Frameworks/Python.framework/Versions/3.12/lib/python3.12/asyncio/base_events.py", line 878, in getaddrinfo
    return await self.run_in_executor(
           ^^^^^^^^^^^^^^^^^^^^^^^^^^^
  File "/Library/Frameworks/Python.framework/Versions/3.12/lib/python3.12/concurrent/futures/thread.py", line 58, in run
    result = self.fn(*self.args, **self.kwargs)
             ^^^^^^^^^^^^^^^^^^^^^^^^^^^^^^^^^^
  File "/Library/Frameworks/Python.framework/Versions/3.12/lib/python3.12/socket.py", line 963, in getaddrinfo
    for res in _socket.getaddrinfo(host, port, family, type, proto, flags):
               ^^^^^^^^^^^^^^^^^^^^^^^^^^^^^^^^^^^^^^^^^^^^^^^^^^^^^^^^^^^
socket.gaierror: [Errno 8] nodename nor servname provided, or not known

The above exception was the direct cause of the following exception:

Traceback (most recent call last):
  File "/Users/tyson/my-discord-bot/venv/lib/python3.12/site-packages/discord/client.py", line 664, in connect
    self.ws = await asyncio.wait_for(coro, timeout=60.0)
              ^^^^^^^^^^^^^^^^^^^^^^^^^^^^^^^^^^^^^^^^^^
  File "/Library/Frameworks/Python.framework/Versions/3.12/lib/python3.12/asyncio/tasks.py", line 510, in wait_for
    return await fut
           ^^^^^^^^^
  File "/Users/tyson/my-discord-bot/venv/lib/python3.12/site-packages/discord/gateway.py", line 374, in from_client
    socket = await client.http.ws_connect(str(url))
             ^^^^^^^^^^^^^^^^^^^^^^^^^^^^^^^^^^^^^^
  File "/Users/tyson/my-discord-bot/venv/lib/python3.12/site-packages/discord/http.py", line 550, in ws_connect
    return await self.__session.ws_connect(url, **kwargs)
           ^^^^^^^^^^^^^^^^^^^^^^^^^^^^^^^^^^^^^^^^^^^^^^
  File "/Users/tyson/my-discord-bot/venv/lib/python3.12/site-packages/aiohttp/client.py", line 935, in _ws_connect
    resp = await self.request(
           ^^^^^^^^^^^^^^^^^^^
  File "/Users/tyson/my-discord-bot/venv/lib/python3.12/site-packages/aiohttp/client.py", line 661, in _request
    conn = await self._connector.connect(
           ^^^^^^^^^^^^^^^^^^^^^^^^^^^^^^
  File "/Users/tyson/my-discord-bot/venv/lib/python3.12/site-packages/aiohttp/connector.py", line 556, in connect
    proto = await self._create_connection(req, traces, timeout)
            ^^^^^^^^^^^^^^^^^^^^^^^^^^^^^^^^^^^^^^^^^^^^^^^^^^^
  File "/Users/tyson/my-discord-bot/venv/lib/python3.12/site-packages/aiohttp/connector.py", line 1009, in _create_connection
    _, proto = await self._create_direct_connection(req, traces, timeout)
               ^^^^^^^^^^^^^^^^^^^^^^^^^^^^^^^^^^^^^^^^^^^^^^^^^^^^^^^^^^
  File "/Users/tyson/my-discord-bot/venv/lib/python3.12/site-packages/aiohttp/connector.py", line 1300, in _create_direct_connection
    raise ClientConnectorError(req.connection_key, exc) from exc
aiohttp.client_exceptions.ClientConnectorError: Cannot connect to host gateway-us-east1-d.discord.gg:443 ssl:default [nodename nor servname provided, or not known]
[2024-10-09 21:36:11] [ERROR   ] discord.client: Attempting a reconnect in 2.26s
Traceback (most recent call last):
  File "/Users/tyson/my-discord-bot/venv/lib/python3.12/site-packages/aiohttp/connector.py", line 1294, in _create_direct_connection
    hosts = await self._resolve_host(host, port, traces=traces)
            ^^^^^^^^^^^^^^^^^^^^^^^^^^^^^^^^^^^^^^^^^^^^^^^^^^^
  File "/Users/tyson/my-discord-bot/venv/lib/python3.12/site-packages/aiohttp/connector.py", line 945, in _resolve_host
    return await asyncio.shield(resolved_host_task)
           ^^^^^^^^^^^^^^^^^^^^^^^^^^^^^^^^^^^^^^^^
  File "/Users/tyson/my-discord-bot/venv/lib/python3.12/site-packages/aiohttp/connector.py", line 982, in _resolve_host_with_throttle
    addrs = await self._resolver.resolve(host, port, family=self._family)
            ^^^^^^^^^^^^^^^^^^^^^^^^^^^^^^^^^^^^^^^^^^^^^^^^^^^^^^^^^^^^^
  File "/Users/tyson/my-discord-bot/venv/lib/python3.12/site-packages/aiohttp/resolver.py", line 38, in resolve
    infos = await self._loop.getaddrinfo(
            ^^^^^^^^^^^^^^^^^^^^^^^^^^^^^
  File "/Library/Frameworks/Python.framework/Versions/3.12/lib/python3.12/asyncio/base_events.py", line 878, in getaddrinfo
    return await self.run_in_executor(
           ^^^^^^^^^^^^^^^^^^^^^^^^^^^
  File "/Library/Frameworks/Python.framework/Versions/3.12/lib/python3.12/concurrent/futures/thread.py", line 58, in run
    result = self.fn(*self.args, **self.kwargs)
             ^^^^^^^^^^^^^^^^^^^^^^^^^^^^^^^^^^
  File "/Library/Frameworks/Python.framework/Versions/3.12/lib/python3.12/socket.py", line 963, in getaddrinfo
    for res in _socket.getaddrinfo(host, port, family, type, proto, flags):
               ^^^^^^^^^^^^^^^^^^^^^^^^^^^^^^^^^^^^^^^^^^^^^^^^^^^^^^^^^^^
socket.gaierror: [Errno 8] nodename nor servname provided, or not known

The above exception was the direct cause of the following exception:

Traceback (most recent call last):
  File "/Users/tyson/my-discord-bot/venv/lib/python3.12/site-packages/discord/client.py", line 664, in connect
    self.ws = await asyncio.wait_for(coro, timeout=60.0)
              ^^^^^^^^^^^^^^^^^^^^^^^^^^^^^^^^^^^^^^^^^^
  File "/Library/Frameworks/Python.framework/Versions/3.12/lib/python3.12/asyncio/tasks.py", line 510, in wait_for
    return await fut
           ^^^^^^^^^
  File "/Users/tyson/my-discord-bot/venv/lib/python3.12/site-packages/discord/gateway.py", line 374, in from_client
    socket = await client.http.ws_connect(str(url))
             ^^^^^^^^^^^^^^^^^^^^^^^^^^^^^^^^^^^^^^
  File "/Users/tyson/my-discord-bot/venv/lib/python3.12/site-packages/discord/http.py", line 550, in ws_connect
    return await self.__session.ws_connect(url, **kwargs)
           ^^^^^^^^^^^^^^^^^^^^^^^^^^^^^^^^^^^^^^^^^^^^^^
  File "/Users/tyson/my-discord-bot/venv/lib/python3.12/site-packages/aiohttp/client.py", line 935, in _ws_connect
    resp = await self.request(
           ^^^^^^^^^^^^^^^^^^^
  File "/Users/tyson/my-discord-bot/venv/lib/python3.12/site-packages/aiohttp/client.py", line 661, in _request
    conn = await self._connector.connect(
           ^^^^^^^^^^^^^^^^^^^^^^^^^^^^^^
  File "/Users/tyson/my-discord-bot/venv/lib/python3.12/site-packages/aiohttp/connector.py", line 556, in connect
    proto = await self._create_connection(req, traces, timeout)
            ^^^^^^^^^^^^^^^^^^^^^^^^^^^^^^^^^^^^^^^^^^^^^^^^^^^
  File "/Users/tyson/my-discord-bot/venv/lib/python3.12/site-packages/aiohttp/connector.py", line 1009, in _create_connection
    _, proto = await self._create_direct_connection(req, traces, timeout)
               ^^^^^^^^^^^^^^^^^^^^^^^^^^^^^^^^^^^^^^^^^^^^^^^^^^^^^^^^^^
  File "/Users/tyson/my-discord-bot/venv/lib/python3.12/site-packages/aiohttp/connector.py", line 1300, in _create_direct_connection
    raise ClientConnectorError(req.connection_key, exc) from exc
aiohttp.client_exceptions.ClientConnectorError: Cannot connect to host gateway-us-east1-d.discord.gg:443 ssl:default [nodename nor servname provided, or not known]
[2024-10-09 21:38:43] [ERROR   ] discord.client: Attempting a reconnect in 1.92s
Traceback (most recent call last):
  File "/Users/tyson/my-discord-bot/venv/lib/python3.12/site-packages/aiohttp/connector.py", line 1294, in _create_direct_connection
    hosts = await self._resolve_host(host, port, traces=traces)
            ^^^^^^^^^^^^^^^^^^^^^^^^^^^^^^^^^^^^^^^^^^^^^^^^^^^
  File "/Users/tyson/my-discord-bot/venv/lib/python3.12/site-packages/aiohttp/connector.py", line 945, in _resolve_host
    return await asyncio.shield(resolved_host_task)
           ^^^^^^^^^^^^^^^^^^^^^^^^^^^^^^^^^^^^^^^^
  File "/Users/tyson/my-discord-bot/venv/lib/python3.12/site-packages/aiohttp/connector.py", line 982, in _resolve_host_with_throttle
    addrs = await self._resolver.resolve(host, port, family=self._family)
            ^^^^^^^^^^^^^^^^^^^^^^^^^^^^^^^^^^^^^^^^^^^^^^^^^^^^^^^^^^^^^
  File "/Users/tyson/my-discord-bot/venv/lib/python3.12/site-packages/aiohttp/resolver.py", line 38, in resolve
    infos = await self._loop.getaddrinfo(
            ^^^^^^^^^^^^^^^^^^^^^^^^^^^^^
  File "/Library/Frameworks/Python.framework/Versions/3.12/lib/python3.12/asyncio/base_events.py", line 878, in getaddrinfo
    return await self.run_in_executor(
           ^^^^^^^^^^^^^^^^^^^^^^^^^^^
  File "/Library/Frameworks/Python.framework/Versions/3.12/lib/python3.12/concurrent/futures/thread.py", line 58, in run
    result = self.fn(*self.args, **self.kwargs)
             ^^^^^^^^^^^^^^^^^^^^^^^^^^^^^^^^^^
  File "/Library/Frameworks/Python.framework/Versions/3.12/lib/python3.12/socket.py", line 963, in getaddrinfo
    for res in _socket.getaddrinfo(host, port, family, type, proto, flags):
               ^^^^^^^^^^^^^^^^^^^^^^^^^^^^^^^^^^^^^^^^^^^^^^^^^^^^^^^^^^^
socket.gaierror: [Errno 8] nodename nor servname provided, or not known

The above exception was the direct cause of the following exception:

Traceback (most recent call last):
  File "/Users/tyson/my-discord-bot/venv/lib/python3.12/site-packages/discord/client.py", line 664, in connect
    self.ws = await asyncio.wait_for(coro, timeout=60.0)
              ^^^^^^^^^^^^^^^^^^^^^^^^^^^^^^^^^^^^^^^^^^
  File "/Library/Frameworks/Python.framework/Versions/3.12/lib/python3.12/asyncio/tasks.py", line 510, in wait_for
    return await fut
           ^^^^^^^^^
  File "/Users/tyson/my-discord-bot/venv/lib/python3.12/site-packages/discord/gateway.py", line 374, in from_client
    socket = await client.http.ws_connect(str(url))
             ^^^^^^^^^^^^^^^^^^^^^^^^^^^^^^^^^^^^^^
  File "/Users/tyson/my-discord-bot/venv/lib/python3.12/site-packages/discord/http.py", line 550, in ws_connect
    return await self.__session.ws_connect(url, **kwargs)
           ^^^^^^^^^^^^^^^^^^^^^^^^^^^^^^^^^^^^^^^^^^^^^^
  File "/Users/tyson/my-discord-bot/venv/lib/python3.12/site-packages/aiohttp/client.py", line 935, in _ws_connect
    resp = await self.request(
           ^^^^^^^^^^^^^^^^^^^
  File "/Users/tyson/my-discord-bot/venv/lib/python3.12/site-packages/aiohttp/client.py", line 661, in _request
    conn = await self._connector.connect(
           ^^^^^^^^^^^^^^^^^^^^^^^^^^^^^^
  File "/Users/tyson/my-discord-bot/venv/lib/python3.12/site-packages/aiohttp/connector.py", line 556, in connect
    proto = await self._create_connection(req, traces, timeout)
            ^^^^^^^^^^^^^^^^^^^^^^^^^^^^^^^^^^^^^^^^^^^^^^^^^^^
  File "/Users/tyson/my-discord-bot/venv/lib/python3.12/site-packages/aiohttp/connector.py", line 1009, in _create_connection
    _, proto = await self._create_direct_connection(req, traces, timeout)
               ^^^^^^^^^^^^^^^^^^^^^^^^^^^^^^^^^^^^^^^^^^^^^^^^^^^^^^^^^^
  File "/Users/tyson/my-discord-bot/venv/lib/python3.12/site-packages/aiohttp/connector.py", line 1300, in _create_direct_connection
    raise ClientConnectorError(req.connection_key, exc) from exc
aiohttp.client_exceptions.ClientConnectorError: Cannot connect to host gateway-us-east1-d.discord.gg:443 ssl:default [nodename nor servname provided, or not known]
[2024-10-09 21:38:45] [ERROR   ] discord.client: Attempting a reconnect in 15.71s
Traceback (most recent call last):
  File "/Users/tyson/my-discord-bot/venv/lib/python3.12/site-packages/aiohttp/connector.py", line 1294, in _create_direct_connection
    hosts = await self._resolve_host(host, port, traces=traces)
            ^^^^^^^^^^^^^^^^^^^^^^^^^^^^^^^^^^^^^^^^^^^^^^^^^^^
  File "/Users/tyson/my-discord-bot/venv/lib/python3.12/site-packages/aiohttp/connector.py", line 945, in _resolve_host
    return await asyncio.shield(resolved_host_task)
           ^^^^^^^^^^^^^^^^^^^^^^^^^^^^^^^^^^^^^^^^
  File "/Users/tyson/my-discord-bot/venv/lib/python3.12/site-packages/aiohttp/connector.py", line 982, in _resolve_host_with_throttle
    addrs = await self._resolver.resolve(host, port, family=self._family)
            ^^^^^^^^^^^^^^^^^^^^^^^^^^^^^^^^^^^^^^^^^^^^^^^^^^^^^^^^^^^^^
  File "/Users/tyson/my-discord-bot/venv/lib/python3.12/site-packages/aiohttp/resolver.py", line 38, in resolve
    infos = await self._loop.getaddrinfo(
            ^^^^^^^^^^^^^^^^^^^^^^^^^^^^^
  File "/Library/Frameworks/Python.framework/Versions/3.12/lib/python3.12/asyncio/base_events.py", line 878, in getaddrinfo
    return await self.run_in_executor(
           ^^^^^^^^^^^^^^^^^^^^^^^^^^^
  File "/Library/Frameworks/Python.framework/Versions/3.12/lib/python3.12/concurrent/futures/thread.py", line 58, in run
    result = self.fn(*self.args, **self.kwargs)
             ^^^^^^^^^^^^^^^^^^^^^^^^^^^^^^^^^^
  File "/Library/Frameworks/Python.framework/Versions/3.12/lib/python3.12/socket.py", line 963, in getaddrinfo
    for res in _socket.getaddrinfo(host, port, family, type, proto, flags):
               ^^^^^^^^^^^^^^^^^^^^^^^^^^^^^^^^^^^^^^^^^^^^^^^^^^^^^^^^^^^
socket.gaierror: [Errno 8] nodename nor servname provided, or not known

The above exception was the direct cause of the following exception:

Traceback (most recent call last):
  File "/Users/tyson/my-discord-bot/venv/lib/python3.12/site-packages/discord/client.py", line 664, in connect
    self.ws = await asyncio.wait_for(coro, timeout=60.0)
              ^^^^^^^^^^^^^^^^^^^^^^^^^^^^^^^^^^^^^^^^^^
  File "/Library/Frameworks/Python.framework/Versions/3.12/lib/python3.12/asyncio/tasks.py", line 510, in wait_for
    return await fut
           ^^^^^^^^^
  File "/Users/tyson/my-discord-bot/venv/lib/python3.12/site-packages/discord/gateway.py", line 374, in from_client
    socket = await client.http.ws_connect(str(url))
             ^^^^^^^^^^^^^^^^^^^^^^^^^^^^^^^^^^^^^^
  File "/Users/tyson/my-discord-bot/venv/lib/python3.12/site-packages/discord/http.py", line 550, in ws_connect
    return await self.__session.ws_connect(url, **kwargs)
           ^^^^^^^^^^^^^^^^^^^^^^^^^^^^^^^^^^^^^^^^^^^^^^
  File "/Users/tyson/my-discord-bot/venv/lib/python3.12/site-packages/aiohttp/client.py", line 935, in _ws_connect
    resp = await self.request(
           ^^^^^^^^^^^^^^^^^^^
  File "/Users/tyson/my-discord-bot/venv/lib/python3.12/site-packages/aiohttp/client.py", line 661, in _request
    conn = await self._connector.connect(
           ^^^^^^^^^^^^^^^^^^^^^^^^^^^^^^
  File "/Users/tyson/my-discord-bot/venv/lib/python3.12/site-packages/aiohttp/connector.py", line 556, in connect
    proto = await self._create_connection(req, traces, timeout)
            ^^^^^^^^^^^^^^^^^^^^^^^^^^^^^^^^^^^^^^^^^^^^^^^^^^^
  File "/Users/tyson/my-discord-bot/venv/lib/python3.12/site-packages/aiohttp/connector.py", line 1009, in _create_connection
    _, proto = await self._create_direct_connection(req, traces, timeout)
               ^^^^^^^^^^^^^^^^^^^^^^^^^^^^^^^^^^^^^^^^^^^^^^^^^^^^^^^^^^
  File "/Users/tyson/my-discord-bot/venv/lib/python3.12/site-packages/aiohttp/connector.py", line 1300, in _create_direct_connection
    raise ClientConnectorError(req.connection_key, exc) from exc
aiohttp.client_exceptions.ClientConnectorError: Cannot connect to host gateway-us-east1-d.discord.gg:443 ssl:default [nodename nor servname provided, or not known]
[2024-10-09 21:43:08] [INFO    ] discord.gateway: Shard ID None session has been invalidated.
[2024-10-09 21:43:14] [INFO    ] discord.gateway: Shard ID None has connected to Gateway (Session ID: f216b22f5b8b924f08e3d3fc04b98c95).
[2024-10-09 22:42:28] [INFO    ] discord.gateway: Shard ID None session has been invalidated.
[2024-10-09 22:42:34] [INFO    ] discord.gateway: Shard ID None has connected to Gateway (Session ID: 55fe27d93deb6c972b24a3ff52262418).
[2024-10-09 23:32:13] [INFO    ] discord.gateway: Shard ID None has successfully RESUMED session 55fe27d93deb6c972b24a3ff52262418.
[2024-10-10 01:23:22] [INFO    ] discord.gateway: Shard ID None has successfully RESUMED session 55fe27d93deb6c972b24a3ff52262418.
[2024-10-10 01:29:12] [INFO    ] discord.gateway: Shard ID None session has been invalidated.
[2024-10-10 01:29:18] [INFO    ] discord.gateway: Shard ID None has connected to Gateway (Session ID: 141a9c91d3b6ecf919c83dc29dd72192).
[2024-10-10 01:33:24] [INFO    ] discord.gateway: Shard ID None session has been invalidated.
[2024-10-10 01:33:30] [INFO    ] discord.gateway: Shard ID None has connected to Gateway (Session ID: fa85e6468e46550615472286a1224f11).
[2024-10-10 01:51:08] [INFO    ] discord.gateway: Shard ID None session has been invalidated.
[2024-10-10 01:51:13] [INFO    ] discord.gateway: Shard ID None has connected to Gateway (Session ID: d915b5e60d0fa5cc7ff7209626e7a072).
[2024-10-10 02:27:47] [INFO    ] discord.gateway: Shard ID None session has been invalidated.
[2024-10-10 02:27:54] [INFO    ] discord.gateway: Shard ID None has connected to Gateway (Session ID: af3e4b8c25f2728daa54b5011991c4ac).
[2024-10-10 02:29:20] [INFO    ] discord.gateway: Shard ID None has successfully RESUMED session af3e4b8c25f2728daa54b5011991c4ac.
[2024-10-10 03:16:18] [INFO    ] discord.gateway: Shard ID None has successfully RESUMED session af3e4b8c25f2728daa54b5011991c4ac.
[2024-10-10 04:52:56] [INFO    ] discord.gateway: Shard ID None has successfully RESUMED session af3e4b8c25f2728daa54b5011991c4ac.
[2024-10-10 05:15:07] [INFO    ] discord.gateway: Shard ID None has successfully RESUMED session af3e4b8c25f2728daa54b5011991c4ac.
[2024-10-10 05:20:47] [INFO    ] discord.gateway: Shard ID None has successfully RESUMED session af3e4b8c25f2728daa54b5011991c4ac.
[2024-10-10 06:35:43] [INFO    ] discord.gateway: Shard ID None has successfully RESUMED session af3e4b8c25f2728daa54b5011991c4ac.
[2024-10-10 08:11:54] [INFO    ] discord.gateway: Shard ID None session has been invalidated.
[2024-10-10 08:12:04] [INFO    ] discord.gateway: Shard ID None has connected to Gateway (Session ID: fc655edc5a032fcaa1eddf53eeac2ab5).
[2024-10-10 08:32:08] [INFO    ] discord.gateway: Shard ID None has successfully RESUMED session fc655edc5a032fcaa1eddf53eeac2ab5.
[2024-10-10 09:18:54] [INFO    ] discord.gateway: Shard ID None session has been invalidated.
[2024-10-10 09:18:59] [INFO    ] discord.gateway: Shard ID None has connected to Gateway (Session ID: 6b8e9e5d87c7c0d4c73f40beab10ab48).
[2024-10-10 10:35:18] [INFO    ] discord.gateway: Shard ID None session has been invalidated.
[2024-10-10 10:35:23] [INFO    ] discord.gateway: Shard ID None has connected to Gateway (Session ID: 47083571a72ce32f33f99b5ff283a4d4).
[2024-10-10 10:54:03] [INFO    ] discord.gateway: Shard ID None session has been invalidated.
[2024-10-10 10:54:09] [INFO    ] discord.gateway: Shard ID None has connected to Gateway (Session ID: dd21131d5ee05c40a0099ffab0c18c43).
[2024-10-10 11:11:07] [INFO    ] discord.gateway: Shard ID None session has been invalidated.
[2024-10-10 11:11:13] [INFO    ] discord.gateway: Shard ID None has connected to Gateway (Session ID: 779f64133088cb3b3689b4349319efce).
[2024-10-10 11:20:11] [INFO    ] discord.gateway: Shard ID None session has been invalidated.
[2024-10-10 11:20:17] [INFO    ] discord.gateway: Shard ID None has connected to Gateway (Session ID: bfebfe5be16ad905c33de4f3533c59f2).
[2024-10-10 11:36:35] [INFO    ] discord.gateway: Shard ID None session has been invalidated.
[2024-10-10 11:36:41] [INFO    ] discord.gateway: Shard ID None has connected to Gateway (Session ID: 38cc481ab05674ddf539679d6f8ba419).
[2024-10-10 12:26:51] [INFO    ] discord.gateway: Shard ID None has successfully RESUMED session 38cc481ab05674ddf539679d6f8ba419.
[2024-10-10 12:51:40] [INFO    ] discord.gateway: Shard ID None has successfully RESUMED session 38cc481ab05674ddf539679d6f8ba419.
[2024-10-10 13:33:27] [INFO    ] discord.gateway: Shard ID None has successfully RESUMED session 38cc481ab05674ddf539679d6f8ba419.
[2024-10-10 17:15:57] [INFO    ] discord.gateway: Shard ID None has successfully RESUMED session 38cc481ab05674ddf539679d6f8ba419.
